Workbook
Name Slicer_City: #N/A
Name Slicer_Product_Purchased: #N/A
Name Slicer_Purchase_Year: #N/A

Sheet Original Data
A1: First Name,Last Name, order I'D, Purchase Date | E1: Product Purchased | F1: Amount Paid | G1: Payment Status | H1: City | I1: Delivery Status
C2: CA-2011-100293 | D2: 41963 | E2: Smartphone | F2: 498.68 | G2: Paid | H2: Mumbai | I2: In Transit
A3: rahul | B3: Gupta | C3: CA-2011-100706 | D3: 41888 | E3: Laptop | F3: 738.76 | G3: Pending | H3: Pune | I3: In Transit
A4: jivika | B4: Ravi | C4: CA-2011-100895 | D4: 44796 | E4: Camera | F4: 1228.47 | G4: Pending | H4: Pune | I4: Delivered
A5: Ranbir | C5: CA-2011-100916 | D5: 43011 | E5: Headphones | F5: 1744.08 | G5: Pending | H5: Surat | I5: In Transit
A6: Vanya | B6: Dutta | C6: CA-2011-101266 | D6: 44647 | E6: Headphones | F6: 164.13 | G6: Paid | H6: Mumbai | I6: Cancelled
A7: Devansh | B7: bhaskar | C7: CA-2011-101560 | D7: 42379 | E7: Camera | F7: 584.97 | G7: Failed | H7: Kolkata
A8: ryan | B8: Krishnamurthy | C8: CA-2011-101770 | D8: 45585 | E8: Laptop | H8: Mumbai | I8: Cancelled
A9: Ivana | B9: Sethi | C9: CA-2011-102274 | D9: 43016 | E9: Keyboard | F9: 587.97 | G9: Pending | H9: Jaipur
A10: nehmat | B10: pal | C10: CA-2011-102673 | D10: 42482 | E10: Smartwatch | F10: 267.58 | G10: Pending | H10: Hyderabad | I10: In Transit
A11: nehmat | B11: pal | C11: CA-2011-102673 | D11: 42482 | E11: Smartwatch | F11: 267.58 | G11: Pending | H11: Hyderabad | I11: In Transit
A12: Aaryahi | B12: VEG | C12: CA-2011-102988 | D12: 42857 | E12: Keyboard | F12: 1323.02 | G12: Failed | H12: Mumbai | I12: Cancelled
B13: Dhar | C13: CA-2011-103317 | D13: 42858 | E13: Smartphone | F13: 1400.9 | G13: Pending | H13: Ahmedabad | I13: In Transit
C14: CA-2011-103366 | D14: 42852 | E14: Monitor | F14: 1587.5 | G14: Paid | H14: Kolkata | I14: In Transit
A15: anahita | B15: Dyal | C15: CA-2011-103807 | D15: 42853 | F15: 1471.32 | G15: Pending | H15: Chennai | I15: Cancelled
A16: Yashvi | C16: CA-2011-103989 | D16: 44735 | E16: Tablet | G16: Pending | H16: Surat | I16: Delivered
A17: Divij | B17: Kapadia | C17: CA-2011-104283 | D17: 44570 | E17: Smartphone | G17: Pending | H17: Chennai | I17: In Transit
A18: Ritvik | B18: Hayer | C18: CA-2011-106054 | D18: 43887 | E18: Camera | F18: 1637.88 | G18: Failed | H18: Bangalore | I18: Cancelled
A19: Dhanush | B19: Bala | C19: CA-2011-106810 | D19: 43888 | E19: Keyboard | F19: 371.93 | G19: Paid | H19: Hyderabad
A20: Himmat | B20: singh | C20: CA-2011-107573 | D20: 43644 | E20: Laptop | F20: 1592.57 | G20: Pending | H20: Delhi | I20: Delivered
A21: Hazel | B21: Choudhary | C21: CA-2011-107811 | D21: 43645 | E21: Tablet | F21: 76.81 | G21: Pending | H21: Kolkata
A22: Himmat | C22: CA-2011-108707 | D22: 42822 | E22: Printer | F22: 1659.26 | G22: Pending | H22: Kolkata | I22: In Transit
A23: Zara | B23: Desai | C23: CA-2011-109043 | D23: 42823 | E23: Tablet | F23: 1043.02 | G23: Pending | H23: Ahmedabad
A24: Samarth | B24: Chand | C24: CA-2011-109232 | D24: 45226 | E24: Tablet | F24: 1549.79 | G24: Pending | H24: Hyderabad | I24: Delivered
A25: Jayan | B25: Srivastava | C25: CA-2011-110100 | D25: 43074 | E25: Printer | G25: Pending | H25: Jaipur | I25: Delivered
A26: Ivan | B26: BOHRA | C26: CA-2011-110408 | D26: 43075 | E26: Printer | G26: Pending | H26: Jaipur | I26: Cancelled
A27: Rohan | B27: Khanna | C27: CA-2011-110422 | D27: 42760 | F27: 893.33 | H27: Kolkata | I27: In Transit
A28: Damini | B28: divan | C28: CA-2011-111500 | D28: 42197 | E28: Laptop | F28: 1556.99 | G28: Pending | H28: Jaipur | I28: Cancelled
A29: Damini | B29: divan | C29: CA-2011-111500 | D29: 42197 | E29: Laptop | F29: 1556.99 | G29: Pending | H29: Jaipur | I29: Cancelled
A30: Amira | C30: CA-2011-111934 | D30: 44685 | E30: Smartphone | F30: 1137.66 | G30: Failed | H30: Delhi | I30: Cancelled
A31: Neelofar | B31: Aurora | C31: CA-2011-112718 | D31: 44611 | E31: Camera | F31: 1055.32 | G31: Failed | H31: Ahmedabad | I31: Cancelled
A32: TARA | B32: Kanda | C32: CA-2011-113047 | D32: 42358 | E32: Monitor | F32: 242.79 | H32: Hyderabad | I32: Cancelled
A33: Navya | B33: Dhar | C33: CA-2011-113166 | F33: 1266.32 | G33: Pending | H33: Ahmedabad | I33: Cancelled
A34: tushar | B34: Kuruvilla | C34: CA-2011-114314 | E34: Mouse | G34: Failed | H34: Surat | I34: In Transit
A35: rania | B35: Sawhney | C35: CA-2011-114321 | D35: 44020 | E35: Keyboard | F35: 806.94 | G35: Paid | H35: Pune | I35: Delivered
B36: Rao | C36: CA-2011-114335 | D36: 44661 | E36: Monitor | F36: 780.26 | G36: Paid | H36: Surat
A37: Adah | B37: BOASE | C37: CA-2011-114790 | D37: 42993 | E37: Mouse | F37: 174.11 | G37: Pending | I37: In Transit
B38: Loyal | C38: CA-2011-115084 | D38: 44806 | E38: Mouse | F38: 474.27 | G38: Paid | H38: Ahmedabad | I38: In Transit
A39: Samarth | B39: Kalita | C39: CA-2011-115357 | D39: 44861 | E39: Tablet | F39: 410.29 | G39: Pending | H39: Chennai | I39: Delivered
A40: Riya | B40: Sengupta | C40: CA-2011-116190 | D40: 44469 | E40: Laptop | F40: 677.52 | G40: Pending | I40: Delivered
...

Sheet Sales
A3: Row Labels | B3: Sum of Amount Paid
A4: 2014 | B4: 4661.52
A5: 8 | B5: 1320.34
A6: 9 | B6: 2232.84
A7: 10 | B7: 510.37
A8: 11 | B8: 597.97
A9: Grand Total | B9: 4661.52
G23: Total Revenue | H23: =GETPIVOTDATA("Amount Paid",$A$3) -> 4661.52

Sheet Orders
A3: Row Labels | B3: Count of order I'D
A4: 2014 | B4: 7
A5: 8 | B5: 1
A6: 9 | B6: 3
A7: 10 | B7: 1
A8: 11 | B8: 2
A9: Grand Total | B9: 7
M21: Total Revenue | N21: =Sales!$H$23 -> 4661.52
M22: Total Orders | N22: =GETPIVOTDATA("order I'D",$A$3) -> 7
D23: =Sales!$H$23 -> 4661.52 | M23: AOV | N23: =D23/GETPIVOTDATA("order I'D",$A$3) -> 665.93143
M24: Payment Success | N24: ='Payment Status'!$O$25 -> 0.41152028
M25: Delivery Success | N25: ='Delivary Status'!$Q$15 -> 0.42857143
M26: Pending Payment | N26: ='Payment Status'!$O$13 -> 0.58847972

Sheet Payment Status
A3: Row Labels | B3: Sum of Amount Paid | C3: Count of order I'D
A4: Paid | B4: 1918.31 | C4: 3
A5: Pending | B5: 2743.21 | C5: 4
A6: Grand Total | B6: 4661.52 | C6: 7
N13: Panding Payment | O13: =GETPIVOTDATA("Sum of Amount Paid",$A$3,"Payment Status","Pending")/GETPIVOTDATA("Sum of Amount Paid",$A$3) -> 0.58847972
N25: Payment Success Rate | O25: =GETPIVOTDATA("Sum of Amount Paid",$A$3,"Payment Status","Paid")/GETPIVOTDATA("Sum of Amount Paid",$A$3) -> 0.41152028
N26: Failure Rate | O26: =GETPIVOTDATA("Sum of Amount Paid",$A$3,"Payment Status","Failed")/GETPIVOTDATA("Sum of Amount Paid",$A$3) -> #REF!

Sheet Delivary Status
A3: Row Labels | B3: Count of order I'D
A4: Cancelled | B4: 2
A5: Delivered | B5: 3
A6: InTransit | B6: 2
A7: Grand Total | B7: 7
P15: Delivery Success Rate | Q15: =GETPIVOTDATA("order I'D",$A$3,"Delivery Status","Delivered")/GETPIVOTDATA("order I'D",$A$3) -> 0.42857143

Sheet Product Analysis
A3: Row Labels | B3: Count of order I'D | C3: Sum of Amount Paid
A4: Laptop | B4: 1 | C4: 738.76
A5: Monitor | B5: 1 | C5: 668.37
A6: Mouse | B6: 1 | C6: 1320.34
A7: Smartwatch | B7: 1 | C7: 76.31
A8: Tablet | B8: 3 | C8: 1857.74
A9: Grand Total | B9: 7 | C9: 4661.52

Sheet City Analsys
A3: Row Labels | B3: Count of order I'D | C3: Sum of Amount Paid
A4: Ahmedabad | B4: 1 | C4: 76.31
A5: Bangalore | B5: 1 | C5: 825.71
A6: Chennai | B6: 1 | C6: 510.37
A7: Hyderabad | B7: 1 | C7: 521.66
A8: Mumbai | B8: 2 | C8: 1988.71
A9: Pune | B9: 1 | C9: 738.76
A10: Grand Total | B10: 7 | C10: 4661.52

Sheet Clean Data
A1: Full Name | B1: order I'D | C1: Purchase Year | D1: Purchase Month | E1: Purchase Date | F1: Product Purchased | G1: Amount Paid | H1: Payment Status | I1: City | J1: Delivery Status
A2: Kiara Kuruvilla | B2: CA-2013-124254 | C2: =YEAR(E2) -> 2014 | D2: =MONTH(Table2[[#This Row],[Purchase Date]]) -> 8 | E2: 41868 | F2: Mouse | G2: 1320.34 | H2: Paid | I2: Mumbai | J2: Delivered
A3: Rahul Gupta | B3: CA-2011-100706 | C3: =YEAR(E3) -> 2014 | D3: =MONTH(Table2[[#This Row],[Purchase Date]]) -> 9 | E3: 41888 | F3: Laptop | G3: 738.76 | H3: Pending | I3: Pune | J3: InTransit
A4: Armaan Mander | B4: CA-2014-117198 | C4: =YEAR(E4) -> 2014 | D4: =MONTH(Table2[[#This Row],[Purchase Date]]) -> 9 | E4: 41888 | F4: Tablet | G4: 825.71 | H4: Pending | I4: Bangalore | J4: Delivered
A5: Kabir Sampath | B5: CA-2012-151624 | C5: =YEAR(E5) -> 2014 | D5: =MONTH(Table2[[#This Row],[Purchase Date]]) -> 9 | E5: 41889 | F5: Monitor | G5: 668.37 | H5: Pending | I5: Mumbai | J5: Cancelled
A6: Aradhya Bhardwaj | B6: CA-2013-102092 | C6: =YEAR(E6) -> 2014 | D6: =MONTH(Table2[[#This Row],[Purchase Date]]) -> 10 | E6: 41917 | F6: Tablet | G6: 510.37 | H6: Pending | I6: Chennai | J6: InTransit
A7: Arhaan Magar | B7: CA-2014-117079 | C7: =YEAR(E7) -> 2014 | D7: =MONTH(Table2[[#This Row],[Purchase Date]]) -> 11 | E7: 41963 | F7: Smartwatch | G7: 76.31 | H7: Paid | I7: Ahmedabad | J7: Cancelled
A8: Yakshit Grewal | B8: CA-2013-159765 | C8: =YEAR(E8) -> 2014 | D8: =MONTH(Table2[[#This Row],[Purchase Date]]) -> 11 | E8: 41969 | F8: Tablet | G8: 521.66 | H8: Paid | I8: Hyderabad | J8: Delivered
A9: Jayesh Vaidya | B9: CA-2014-110310 | C9: =YEAR(E9) -> 2015 | D9: =MONTH(Table2[[#This Row],[Purchase Date]]) -> 1 | E9: 42022 | F9: Tablet | G9: 420.84 | H9: Paid | I9: Bangalore | J9: Delivered
A10: Aayush Khatri | B10: CA-2013-166485 | C10: =YEAR(E10) -> 2015 | D10: =MONTH(Table2[[#This Row],[Purchase Date]]) -> 2 | E10: 42037 | F10: Tablet | G10: 1103.28 | H10: Paid | I10: Chennai | J10: InTransit
A11: Rohan Rana | B11: CA-2012-108119 | C11: =YEAR(E11) -> 2015 | D11: =MONTH(Table2[[#This Row],[Purchase Date]]) -> 2 | E11: 42050 | F11: Laptop | G11: 601.53 | H11: Failed | I11: Surat | J11: Cancelled
A12: Rohan Sane | B12: CA-2012-161445 | C12: =YEAR(E12) -> 2015 | D12: =MONTH(Table2[[#This Row],[Purchase Date]]) -> 3 | E12: 42071 | F12: Smartwatch | G12: 130.07 | H12: Failed | I12: Pune | J12: Delivered
A13: Anvi Deol | B13: CA-2013-143805 | C13: =YEAR(E13) -> 2015 | D13: =MONTH(Table2[[#This Row],[Purchase Date]]) -> 6 | E13: 42170 | F13: Keyboard | G13: 1726.07 | H13: Paid | I13: Kolkata | J13: Delivered
... A245: Neelofar Mani | B245: CA-2011-160773 | C245: =YEAR(E245) -> 2024 | D245: =MONTH(Table2[[#This Row],[Purchase Date]]) -> 6 | E245: 45470 | F245: Monitor | G245: 1559.04 | H245: Pending | I245: Delhi | J245: Cancelled

Sheet DashBoard
